[2024-04-17T02:54:25.596+0000] {local_task_job_runner.py:120} INFO - ::group::Pre task execution logs
[2024-04-17T02:54:25.614+0000] {taskinstance.py:2073} INFO - Dependencies all met for dep_context=non-requeueable deps ti=<TaskInstance: financial_data_pipeline.analyze_data manual__2024-04-17T02:54:15.935344+00:00 [queued]>
[2024-04-17T02:54:25.621+0000] {taskinstance.py:2073} INFO - Dependencies all met for dep_context=requeueable deps ti=<TaskInstance: financial_data_pipeline.analyze_data manual__2024-04-17T02:54:15.935344+00:00 [queued]>
[2024-04-17T02:54:25.622+0000] {taskinstance.py:2303} INFO - Starting attempt 1 of 2
[2024-04-17T02:54:25.632+0000] {taskinstance.py:2327} INFO - Executing <Task(PythonOperator): analyze_data> on 2024-04-17 02:54:15.935344+00:00
[2024-04-17T02:54:25.636+0000] {warnings.py:110} WARNING - /home/***/.local/lib/python3.12/site-packages/***/task/task_runner/standard_task_runner.py:61: DeprecationWarning: This process (pid=90) is multi-threaded, use of fork() may lead to deadlocks in the child.
  pid = os.fork()

[2024-04-17T02:54:25.638+0000] {standard_task_runner.py:63} INFO - Started process 94 to run task
[2024-04-17T02:54:25.638+0000] {standard_task_runner.py:90} INFO - Running: ['***', 'tasks', 'run', 'financial_data_pipeline', 'analyze_data', 'manual__2024-04-17T02:54:15.935344+00:00', '--job-id', '113', '--raw', '--subdir', 'DAGS_FOLDER/financial_data_pipeline.py', '--cfg-path', '/tmp/tmp34o78vb6']
[2024-04-17T02:54:25.640+0000] {standard_task_runner.py:91} INFO - Job 113: Subtask analyze_data
[2024-04-17T02:54:25.680+0000] {task_command.py:426} INFO - Running <TaskInstance: financial_data_pipeline.analyze_data manual__2024-04-17T02:54:15.935344+00:00 [running]> on host 637135a7c74f
[2024-04-17T02:54:25.742+0000] {taskinstance.py:2644} INFO - Exporting env vars: AIRFLOW_CTX_DAG_OWNER='***' AIRFLOW_CTX_DAG_ID='financial_data_pipeline' AIRFLOW_CTX_TASK_ID='analyze_data' AIRFLOW_CTX_EXECUTION_DATE='2024-04-17T02:54:15.935344+00:00' AIRFLOW_CTX_TRY_NUMBER='1' AIRFLOW_CTX_DAG_RUN_ID='manual__2024-04-17T02:54:15.935344+00:00'
[2024-04-17T02:54:25.744+0000] {taskinstance.py:430} INFO - ::endgroup::
[2024-04-17T02:54:25.753+0000] {logging_mixin.py:188} INFO - An error occurred: connection to server at "localhost" (::1), port 5432 failed: Connection refused
	Is the server running on that host and accepting TCP/IP connections?
connection to server at "localhost" (127.0.0.1), port 5432 failed: Connection refused
	Is the server running on that host and accepting TCP/IP connections?
[2024-04-17T02:54:25.756+0000] {logging_mixin.py:188} INFO - No data available for analysis.
[2024-04-17T02:54:25.756+0000] {python.py:237} INFO - Done. Returned value was: None
[2024-04-17T02:54:25.757+0000] {taskinstance.py:441} INFO - ::group::Post task execution logs
[2024-04-17T02:54:25.766+0000] {taskinstance.py:1205} INFO - Marking task as SUCCESS. dag_id=financial_data_pipeline, task_id=analyze_data, execution_date=20240417T025415, start_date=20240417T025425, end_date=20240417T025425
[2024-04-17T02:54:25.813+0000] {local_task_job_runner.py:240} INFO - Task exited with return code 0
[2024-04-17T02:54:25.826+0000] {taskinstance.py:3482} INFO - 0 downstream tasks scheduled from follow-on schedule check
[2024-04-17T02:54:25.828+0000] {local_task_job_runner.py:222} INFO - ::endgroup::
