[2024-04-20T00:33:05.788+0000] {local_task_job_runner.py:120} INFO - ::group::Pre task execution logs
[2024-04-20T00:33:05.807+0000] {taskinstance.py:2073} INFO - Dependencies all met for dep_context=non-requeueable deps ti=<TaskInstance: financial_data_pipeline.analyze_data scheduled__2024-04-17T00:00:00+00:00 [queued]>
[2024-04-20T00:33:05.813+0000] {taskinstance.py:2073} INFO - Dependencies all met for dep_context=requeueable deps ti=<TaskInstance: financial_data_pipeline.analyze_data scheduled__2024-04-17T00:00:00+00:00 [queued]>
[2024-04-20T00:33:05.814+0000] {taskinstance.py:2303} INFO - Starting attempt 1 of 2
[2024-04-20T00:33:05.826+0000] {taskinstance.py:2327} INFO - Executing <Task(PythonOperator): analyze_data> on 2024-04-17 00:00:00+00:00
[2024-04-20T00:33:05.835+0000] {warnings.py:110} WARNING - /home/***/.local/lib/python3.12/site-packages/***/task/task_runner/standard_task_runner.py:61: DeprecationWarning: This process (pid=112) is multi-threaded, use of fork() may lead to deadlocks in the child.
  pid = os.fork()

[2024-04-20T00:33:05.837+0000] {standard_task_runner.py:63} INFO - Started process 125 to run task
[2024-04-20T00:33:05.835+0000] {standard_task_runner.py:90} INFO - Running: ['***', 'tasks', 'run', 'financial_data_pipeline', 'analyze_data', 'scheduled__2024-04-17T00:00:00+00:00', '--job-id', '126', '--raw', '--subdir', 'DAGS_FOLDER/financial_data_pipeline.py', '--cfg-path', '/tmp/tmpsvi43sc7']
[2024-04-20T00:33:05.838+0000] {standard_task_runner.py:91} INFO - Job 126: Subtask analyze_data
[2024-04-20T00:33:05.879+0000] {task_command.py:426} INFO - Running <TaskInstance: financial_data_pipeline.analyze_data scheduled__2024-04-17T00:00:00+00:00 [running]> on host 8f675f011065
[2024-04-20T00:33:05.944+0000] {taskinstance.py:2644} INFO - Exporting env vars: AIRFLOW_CTX_DAG_OWNER='***' AIRFLOW_CTX_DAG_ID='financial_data_pipeline' AIRFLOW_CTX_TASK_ID='analyze_data' AIRFLOW_CTX_EXECUTION_DATE='2024-04-17T00:00:00+00:00' AIRFLOW_CTX_TRY_NUMBER='1' AIRFLOW_CTX_DAG_RUN_ID='scheduled__2024-04-17T00:00:00+00:00'
[2024-04-20T00:33:05.946+0000] {taskinstance.py:430} INFO - ::endgroup::
[2024-04-20T00:33:05.956+0000] {logging_mixin.py:188} INFO - An error occurred: connection to server at "localhost" (::1), port 5432 failed: Connection refused
	Is the server running on that host and accepting TCP/IP connections?
connection to server at "localhost" (127.0.0.1), port 5432 failed: Connection refused
	Is the server running on that host and accepting TCP/IP connections?
[2024-04-20T00:33:05.959+0000] {logging_mixin.py:188} INFO - No data available for analysis.
[2024-04-20T00:33:05.960+0000] {python.py:237} INFO - Done. Returned value was: None
[2024-04-20T00:33:05.961+0000] {taskinstance.py:441} INFO - ::group::Post task execution logs
[2024-04-20T00:33:05.969+0000] {taskinstance.py:1205} INFO - Marking task as SUCCESS. dag_id=financial_data_pipeline, task_id=analyze_data, execution_date=20240417T000000, start_date=20240420T003305, end_date=20240420T003305
[2024-04-20T00:33:06.011+0000] {local_task_job_runner.py:240} INFO - Task exited with return code 0
[2024-04-20T00:33:06.024+0000] {taskinstance.py:3482} INFO - 0 downstream tasks scheduled from follow-on schedule check
[2024-04-20T00:33:06.026+0000] {local_task_job_runner.py:222} INFO - ::endgroup::
