[2024-04-17T02:24:35.932+0000] {local_task_job_runner.py:120} INFO - ::group::Pre task execution logs
[2024-04-17T02:24:35.946+0000] {taskinstance.py:2073} INFO - Dependencies all met for dep_context=non-requeueable deps ti=<TaskInstance: financial_data_pipeline.load_data_to_db manual__2024-04-17T02:24:29.143270+00:00 [queued]>
[2024-04-17T02:24:35.953+0000] {taskinstance.py:2073} INFO - Dependencies all met for dep_context=requeueable deps ti=<TaskInstance: financial_data_pipeline.load_data_to_db manual__2024-04-17T02:24:29.143270+00:00 [queued]>
[2024-04-17T02:24:35.954+0000] {taskinstance.py:2303} INFO - Starting attempt 1 of 2
[2024-04-17T02:24:35.963+0000] {taskinstance.py:2327} INFO - Executing <Task(PythonOperator): load_data_to_db> on 2024-04-17 02:24:29.143270+00:00
[2024-04-17T02:24:35.969+0000] {warnings.py:110} WARNING - /home/***/.local/lib/python3.12/site-packages/***/task/task_runner/standard_task_runner.py:61: DeprecationWarning: This process (pid=389) is multi-threaded, use of fork() may lead to deadlocks in the child.
  pid = os.fork()

[2024-04-17T02:24:35.970+0000] {standard_task_runner.py:63} INFO - Started process 393 to run task
[2024-04-17T02:24:35.970+0000] {standard_task_runner.py:90} INFO - Running: ['***', 'tasks', 'run', 'financial_data_pipeline', 'load_data_to_db', 'manual__2024-04-17T02:24:29.143270+00:00', '--job-id', '100', '--raw', '--subdir', 'DAGS_FOLDER/financial_data_pipeline.py', '--cfg-path', '/tmp/tmpdev1k8al']
[2024-04-17T02:24:35.972+0000] {standard_task_runner.py:91} INFO - Job 100: Subtask load_data_to_db
[2024-04-17T02:24:36.007+0000] {task_command.py:426} INFO - Running <TaskInstance: financial_data_pipeline.load_data_to_db manual__2024-04-17T02:24:29.143270+00:00 [running]> on host ca14a7f50ef7
[2024-04-17T02:24:36.068+0000] {taskinstance.py:2644} INFO - Exporting env vars: AIRFLOW_CTX_DAG_OWNER='***' AIRFLOW_CTX_DAG_ID='financial_data_pipeline' AIRFLOW_CTX_TASK_ID='load_data_to_db' AIRFLOW_CTX_EXECUTION_DATE='2024-04-17T02:24:29.143270+00:00' AIRFLOW_CTX_TRY_NUMBER='1' AIRFLOW_CTX_DAG_RUN_ID='manual__2024-04-17T02:24:29.143270+00:00'
[2024-04-17T02:24:36.070+0000] {taskinstance.py:430} INFO - ::endgroup::
[2024-04-17T02:24:36.091+0000] {logging_mixin.py:188} INFO - An error occurred: connection to server at "localhost" (::1), port 5432 failed: Connection refused
	Is the server running on that host and accepting TCP/IP connections?
connection to server at "localhost" (127.0.0.1), port 5432 failed: Connection refused
	Is the server running on that host and accepting TCP/IP connections?
[2024-04-17T02:24:36.092+0000] {python.py:237} INFO - Done. Returned value was: None
[2024-04-17T02:24:36.093+0000] {taskinstance.py:441} INFO - ::group::Post task execution logs
[2024-04-17T02:24:36.100+0000] {taskinstance.py:1205} INFO - Marking task as SUCCESS. dag_id=financial_data_pipeline, task_id=load_data_to_db, execution_date=20240417T022429, start_date=20240417T022435, end_date=20240417T022436
[2024-04-17T02:24:36.144+0000] {local_task_job_runner.py:240} INFO - Task exited with return code 0
[2024-04-17T02:24:36.162+0000] {taskinstance.py:3482} INFO - 1 downstream tasks scheduled from follow-on schedule check
[2024-04-17T02:24:36.164+0000] {local_task_job_runner.py:222} INFO - ::endgroup::
