[2024-04-17T02:50:30.370+0000] {local_task_job_runner.py:120} INFO - ::group::Pre task execution logs
[2024-04-17T02:50:30.395+0000] {taskinstance.py:2073} INFO - Dependencies all met for dep_context=non-requeueable deps ti=<TaskInstance: financial_data_pipeline.analyze_data manual__2024-04-17T02:50:20.222986+00:00 [queued]>
[2024-04-17T02:50:30.403+0000] {taskinstance.py:2073} INFO - Dependencies all met for dep_context=requeueable deps ti=<TaskInstance: financial_data_pipeline.analyze_data manual__2024-04-17T02:50:20.222986+00:00 [queued]>
[2024-04-17T02:50:30.413+0000] {taskinstance.py:2303} INFO - Starting attempt 1 of 2
[2024-04-17T02:50:30.434+0000] {taskinstance.py:2327} INFO - Executing <Task(PythonOperator): analyze_data> on 2024-04-17 02:50:20.222986+00:00
[2024-04-17T02:50:30.445+0000] {warnings.py:110} WARNING - /home/***/.local/lib/python3.12/site-packages/***/task/task_runner/standard_task_runner.py:61: DeprecationWarning: This process (pid=104) is multi-threaded, use of fork() may lead to deadlocks in the child.
  pid = os.fork()

[2024-04-17T02:50:30.447+0000] {standard_task_runner.py:90} INFO - Running: ['***', 'tasks', 'run', 'financial_data_pipeline', 'analyze_data', 'manual__2024-04-17T02:50:20.222986+00:00', '--job-id', '107', '--raw', '--subdir', 'DAGS_FOLDER/financial_data_pipeline.py', '--cfg-path', '/tmp/tmprpu_p4bn']
[2024-04-17T02:50:30.461+0000] {standard_task_runner.py:63} INFO - Started process 108 to run task
[2024-04-17T02:50:30.466+0000] {standard_task_runner.py:91} INFO - Job 107: Subtask analyze_data
[2024-04-17T02:50:30.513+0000] {task_command.py:426} INFO - Running <TaskInstance: financial_data_pipeline.analyze_data manual__2024-04-17T02:50:20.222986+00:00 [running]> on host 6e60764920ec
[2024-04-17T02:50:30.580+0000] {taskinstance.py:2644} INFO - Exporting env vars: AIRFLOW_CTX_DAG_OWNER='***' AIRFLOW_CTX_DAG_ID='financial_data_pipeline' AIRFLOW_CTX_TASK_ID='analyze_data' AIRFLOW_CTX_EXECUTION_DATE='2024-04-17T02:50:20.222986+00:00' AIRFLOW_CTX_TRY_NUMBER='1' AIRFLOW_CTX_DAG_RUN_ID='manual__2024-04-17T02:50:20.222986+00:00'
[2024-04-17T02:50:30.589+0000] {taskinstance.py:430} INFO - ::endgroup::
[2024-04-17T02:50:30.605+0000] {logging_mixin.py:188} INFO - An error occurred: connection to server at "localhost" (::1), port 5432 failed: Connection refused
	Is the server running on that host and accepting TCP/IP connections?
connection to server at "localhost" (127.0.0.1), port 5432 failed: Connection refused
	Is the server running on that host and accepting TCP/IP connections?
[2024-04-17T02:50:30.612+0000] {logging_mixin.py:188} INFO - No data available for analysis.
[2024-04-17T02:50:30.617+0000] {python.py:237} INFO - Done. Returned value was: None
[2024-04-17T02:50:30.623+0000] {taskinstance.py:441} INFO - ::group::Post task execution logs
[2024-04-17T02:50:30.632+0000] {taskinstance.py:1205} INFO - Marking task as SUCCESS. dag_id=financial_data_pipeline, task_id=analyze_data, execution_date=20240417T025020, start_date=20240417T025030, end_date=20240417T025030
[2024-04-17T02:50:30.683+0000] {local_task_job_runner.py:240} INFO - Task exited with return code 0
[2024-04-17T02:50:30.697+0000] {taskinstance.py:3482} INFO - 0 downstream tasks scheduled from follow-on schedule check
[2024-04-17T02:50:30.700+0000] {local_task_job_runner.py:222} INFO - ::endgroup::
