[2024-04-17T02:54:23.284+0000] {local_task_job_runner.py:120} INFO - ::group::Pre task execution logs
[2024-04-17T02:54:23.300+0000] {taskinstance.py:2073} INFO - Dependencies all met for dep_context=non-requeueable deps ti=<TaskInstance: financial_data_pipeline.load_data_to_db manual__2024-04-17T02:54:15.935344+00:00 [queued]>
[2024-04-17T02:54:23.306+0000] {taskinstance.py:2073} INFO - Dependencies all met for dep_context=requeueable deps ti=<TaskInstance: financial_data_pipeline.load_data_to_db manual__2024-04-17T02:54:15.935344+00:00 [queued]>
[2024-04-17T02:54:23.307+0000] {taskinstance.py:2303} INFO - Starting attempt 1 of 2
[2024-04-17T02:54:23.317+0000] {taskinstance.py:2327} INFO - Executing <Task(PythonOperator): load_data_to_db> on 2024-04-17 02:54:15.935344+00:00
[2024-04-17T02:54:23.322+0000] {warnings.py:110} WARNING - /home/***/.local/lib/python3.12/site-packages/***/task/task_runner/standard_task_runner.py:61: DeprecationWarning: This process (pid=85) is multi-threaded, use of fork() may lead to deadlocks in the child.
  pid = os.fork()

[2024-04-17T02:54:23.323+0000] {standard_task_runner.py:63} INFO - Started process 89 to run task
[2024-04-17T02:54:23.323+0000] {standard_task_runner.py:90} INFO - Running: ['***', 'tasks', 'run', 'financial_data_pipeline', 'load_data_to_db', 'manual__2024-04-17T02:54:15.935344+00:00', '--job-id', '112', '--raw', '--subdir', 'DAGS_FOLDER/financial_data_pipeline.py', '--cfg-path', '/tmp/tmphcnvhufo']
[2024-04-17T02:54:23.325+0000] {standard_task_runner.py:91} INFO - Job 112: Subtask load_data_to_db
[2024-04-17T02:54:23.364+0000] {task_command.py:426} INFO - Running <TaskInstance: financial_data_pipeline.load_data_to_db manual__2024-04-17T02:54:15.935344+00:00 [running]> on host 637135a7c74f
[2024-04-17T02:54:23.425+0000] {taskinstance.py:2644} INFO - Exporting env vars: AIRFLOW_CTX_DAG_OWNER='***' AIRFLOW_CTX_DAG_ID='financial_data_pipeline' AIRFLOW_CTX_TASK_ID='load_data_to_db' AIRFLOW_CTX_EXECUTION_DATE='2024-04-17T02:54:15.935344+00:00' AIRFLOW_CTX_TRY_NUMBER='1' AIRFLOW_CTX_DAG_RUN_ID='manual__2024-04-17T02:54:15.935344+00:00'
[2024-04-17T02:54:23.429+0000] {taskinstance.py:430} INFO - ::endgroup::
[2024-04-17T02:54:23.449+0000] {logging_mixin.py:188} INFO - An error occurred: connection to server at "localhost" (::1), port 5432 failed: Connection refused
	Is the server running on that host and accepting TCP/IP connections?
connection to server at "localhost" (127.0.0.1), port 5432 failed: Connection refused
	Is the server running on that host and accepting TCP/IP connections?
[2024-04-17T02:54:23.450+0000] {python.py:237} INFO - Done. Returned value was: None
[2024-04-17T02:54:23.450+0000] {taskinstance.py:441} INFO - ::group::Post task execution logs
[2024-04-17T02:54:23.457+0000] {taskinstance.py:1205} INFO - Marking task as SUCCESS. dag_id=financial_data_pipeline, task_id=load_data_to_db, execution_date=20240417T025415, start_date=20240417T025423, end_date=20240417T025423
[2024-04-17T02:54:23.499+0000] {local_task_job_runner.py:240} INFO - Task exited with return code 0
[2024-04-17T02:54:23.514+0000] {taskinstance.py:3482} INFO - 1 downstream tasks scheduled from follow-on schedule check
[2024-04-17T02:54:23.516+0000] {local_task_job_runner.py:222} INFO - ::endgroup::
