[2024-04-17T02:08:57.809+0000] {local_task_job_runner.py:120} INFO - ::group::Pre task execution logs
[2024-04-17T02:08:57.827+0000] {taskinstance.py:2073} INFO - Dependencies all met for dep_context=non-requeueable deps ti=<TaskInstance: financial_data_pipeline.load_data_to_db scheduled__2024-04-13T00:00:00+00:00 [queued]>
[2024-04-17T02:08:57.835+0000] {taskinstance.py:2073} INFO - Dependencies all met for dep_context=requeueable deps ti=<TaskInstance: financial_data_pipeline.load_data_to_db scheduled__2024-04-13T00:00:00+00:00 [queued]>
[2024-04-17T02:08:57.836+0000] {taskinstance.py:2303} INFO - Starting attempt 1 of 2
[2024-04-17T02:08:57.850+0000] {taskinstance.py:2327} INFO - Executing <Task(PythonOperator): load_data_to_db> on 2024-04-13 00:00:00+00:00
[2024-04-17T02:08:57.858+0000] {warnings.py:110} WARNING - /home/***/.local/lib/python3.12/site-packages/***/task/task_runner/standard_task_runner.py:61: DeprecationWarning: This process (pid=126) is multi-threaded, use of fork() may lead to deadlocks in the child.
  pid = os.fork()

[2024-04-17T02:08:57.860+0000] {standard_task_runner.py:63} INFO - Started process 146 to run task
[2024-04-17T02:08:57.862+0000] {standard_task_runner.py:90} INFO - Running: ['***', 'tasks', 'run', 'financial_data_pipeline', 'load_data_to_db', 'scheduled__2024-04-13T00:00:00+00:00', '--job-id', '91', '--raw', '--subdir', 'DAGS_FOLDER/financial_data_pipeline.py', '--cfg-path', '/tmp/tmppgde_082']
[2024-04-17T02:08:57.864+0000] {standard_task_runner.py:91} INFO - Job 91: Subtask load_data_to_db
[2024-04-17T02:08:57.908+0000] {task_command.py:426} INFO - Running <TaskInstance: financial_data_pipeline.load_data_to_db scheduled__2024-04-13T00:00:00+00:00 [running]> on host ca14a7f50ef7
[2024-04-17T02:08:57.977+0000] {taskinstance.py:2644} INFO - Exporting env vars: AIRFLOW_CTX_DAG_OWNER='***' AIRFLOW_CTX_DAG_ID='financial_data_pipeline' AIRFLOW_CTX_TASK_ID='load_data_to_db' AIRFLOW_CTX_EXECUTION_DATE='2024-04-13T00:00:00+00:00' AIRFLOW_CTX_TRY_NUMBER='1' AIRFLOW_CTX_DAG_RUN_ID='scheduled__2024-04-13T00:00:00+00:00'
[2024-04-17T02:08:57.978+0000] {taskinstance.py:430} INFO - ::endgroup::
[2024-04-17T02:08:57.998+0000] {logging_mixin.py:188} INFO - An error occurred: connection to server at "localhost" (::1), port 5432 failed: Connection refused
	Is the server running on that host and accepting TCP/IP connections?
connection to server at "localhost" (127.0.0.1), port 5432 failed: Connection refused
	Is the server running on that host and accepting TCP/IP connections?
[2024-04-17T02:08:57.999+0000] {python.py:237} INFO - Done. Returned value was: None
[2024-04-17T02:08:58.000+0000] {taskinstance.py:441} INFO - ::group::Post task execution logs
[2024-04-17T02:08:58.008+0000] {taskinstance.py:1205} INFO - Marking task as SUCCESS. dag_id=financial_data_pipeline, task_id=load_data_to_db, execution_date=20240413T000000, start_date=20240417T020857, end_date=20240417T020858
[2024-04-17T02:08:58.034+0000] {local_task_job_runner.py:240} INFO - Task exited with return code 0
[2024-04-17T02:08:58.056+0000] {taskinstance.py:3482} INFO - 1 downstream tasks scheduled from follow-on schedule check
[2024-04-17T02:08:58.058+0000] {local_task_job_runner.py:222} INFO - ::endgroup::
